[2024-05-28T20:48:21.315+0000] {local_task_job_runner.py:120} INFO - ::group::Pre task execution logs
[2024-05-28T20:48:21.341+0000] {taskinstance.py:2076} INFO - Dependencies all met for dep_context=non-requeueable deps ti=<TaskInstance: sales_pipeline.data_delivery manual__2024-05-28T20:46:58.975383+00:00 [queued]>
[2024-05-28T20:48:21.351+0000] {taskinstance.py:2076} INFO - Dependencies all met for dep_context=requeueable deps ti=<TaskInstance: sales_pipeline.data_delivery manual__2024-05-28T20:46:58.975383+00:00 [queued]>
[2024-05-28T20:48:21.352+0000] {taskinstance.py:2306} INFO - Starting attempt 2 of 2
[2024-05-28T20:48:21.365+0000] {taskinstance.py:2330} INFO - Executing <Task(PythonOperator): data_delivery> on 2024-05-28 20:46:58.975383+00:00
[2024-05-28T20:48:21.374+0000] {warnings.py:110} WARNING - /home/***/.local/lib/python3.12/site-packages/***/task/task_runner/standard_task_runner.py:61: DeprecationWarning: This process (pid=225) is multi-threaded, use of fork() may lead to deadlocks in the child.
  pid = os.fork()

[2024-05-28T20:48:21.375+0000] {standard_task_runner.py:63} INFO - Started process 227 to run task
[2024-05-28T20:48:21.375+0000] {standard_task_runner.py:90} INFO - Running: ['***', 'tasks', 'run', 'sales_pipeline', 'data_delivery', 'manual__2024-05-28T20:46:58.975383+00:00', '--job-id', '60', '--raw', '--subdir', 'DAGS_FOLDER/sales_data_pipeline.py', '--cfg-path', '/tmp/tmpcu0vn2mx']
[2024-05-28T20:48:21.377+0000] {standard_task_runner.py:91} INFO - Job 60: Subtask data_delivery
[2024-05-28T20:48:21.388+0000] {warnings.py:110} WARNING - /home/***/.local/lib/python3.12/site-packages/***/settings.py:195: DeprecationWarning: The sql_alchemy_conn option in [core] has been moved to the sql_alchemy_conn option in [database] - the old setting has been used, but please update your config.
  SQL_ALCHEMY_CONN = conf.get("database", "SQL_ALCHEMY_CONN")

[2024-05-28T20:48:21.416+0000] {task_command.py:426} INFO - Running <TaskInstance: sales_pipeline.data_delivery manual__2024-05-28T20:46:58.975383+00:00 [running]> on host 90e12a9d37bb
[2024-05-28T20:48:21.498+0000] {taskinstance.py:2648} INFO - Exporting env vars: AIRFLOW_CTX_DAG_OWNER='Mahmoud Mamdoh' AIRFLOW_CTX_DAG_ID='sales_pipeline' AIRFLOW_CTX_TASK_ID='data_delivery' AIRFLOW_CTX_EXECUTION_DATE='2024-05-28T20:46:58.975383+00:00' AIRFLOW_CTX_TRY_NUMBER='2' AIRFLOW_CTX_DAG_RUN_ID='manual__2024-05-28T20:46:58.975383+00:00'
[2024-05-28T20:48:21.500+0000] {taskinstance.py:430} INFO - ::endgroup::
[2024-05-28T20:48:21.512+0000] {sales_data_pipeline.py:54} INFO - data_delivery started
[2024-05-28T20:48:21.513+0000] {Load_data.py:10} INFO - Loading customer_df dimension...
[2024-05-28T20:48:21.520+0000] {tables_creation.py:47} INFO - Loading data into table DIM_CUSTOMERS...
[2024-05-28T20:48:21.526+0000] {db_utils.py:30} INFO - Connected to PostgreSQL database successfully
[2024-05-28T20:48:21.532+0000] {Load_data.py:19} ERROR - Error loading users dimension: column "naem" of relation "dim_customers" does not exist
LINE 1: INSERT INTO DIM_CUSTOMERS (customer_id, naem, segment, start...
                                                ^

[2024-05-28T20:48:21.533+0000] {Load_data.py:23} INFO - Loading customer dimension...
[2024-05-28T20:48:21.538+0000] {tables_creation.py:47} INFO - Loading data into table DIM_STORE...
[2024-05-28T20:48:21.541+0000] {db_utils.py:30} INFO - Connected to PostgreSQL database successfully
[2024-05-28T20:48:22.271+0000] {tables_creation.py:59} INFO - Data loaded successfully into table DIM_STORE
[2024-05-28T20:48:22.272+0000] {db_utils.py:39} INFO - PostgreSQL connection is closed
[2024-05-28T20:48:22.272+0000] {Load_data.py:29} INFO - store_df dimension loaded successfully
[2024-05-28T20:48:22.289+0000] {Load_data.py:36} INFO - Loading customer dimension...
[2024-05-28T20:48:22.306+0000] {tables_creation.py:47} INFO - Loading data into table DIM_PRODUCT...
[2024-05-28T20:48:22.309+0000] {db_utils.py:30} INFO - Connected to PostgreSQL database successfully
[2024-05-28T20:48:24.531+0000] {tables_creation.py:59} INFO - Data loaded successfully into table DIM_PRODUCT
[2024-05-28T20:48:24.531+0000] {db_utils.py:39} INFO - PostgreSQL connection is closed
[2024-05-28T20:48:24.531+0000] {Load_data.py:42} INFO - product_df dimension loaded successfully
[2024-05-28T20:48:24.584+0000] {Load_data.py:49} INFO - Loading fact sales ...
[2024-05-28T20:48:24.674+0000] {tables_creation.py:47} INFO - Loading data into table FACT_SALES...
[2024-05-28T20:48:24.677+0000] {db_utils.py:30} INFO - Connected to PostgreSQL database successfully
[2024-05-28T20:48:36.988+0000] {tables_creation.py:59} INFO - Data loaded successfully into table FACT_SALES
[2024-05-28T20:48:36.988+0000] {db_utils.py:39} INFO - PostgreSQL connection is closed
[2024-05-28T20:48:37.305+0000] {Load_data.py:53} INFO - Sales fact loaded successfully
[2024-05-28T20:48:37.308+0000] {sales_data_pipeline.py:59} INFO - data_delivery done
[2024-05-28T20:48:37.309+0000] {python.py:237} INFO - Done. Returned value was: None
[2024-05-28T20:48:37.309+0000] {taskinstance.py:441} INFO - ::group::Post task execution logs
[2024-05-28T20:48:37.318+0000] {taskinstance.py:1206} INFO - Marking task as SUCCESS. dag_id=sales_pipeline, task_id=data_delivery, run_id=manual__2024-05-28T20:46:58.975383+00:00, execution_date=20240528T204658, start_date=20240528T204821, end_date=20240528T204837
[2024-05-28T20:48:37.350+0000] {local_task_job_runner.py:240} INFO - Task exited with return code 0
[2024-05-28T20:48:37.363+0000] {taskinstance.py:3498} INFO - 0 downstream tasks scheduled from follow-on schedule check
[2024-05-28T20:48:37.364+0000] {local_task_job_runner.py:222} INFO - ::endgroup::
