[2024-05-28T22:16:01.838+0000] {local_task_job_runner.py:120} INFO - ::group::Pre task execution logs
[2024-05-28T22:16:01.860+0000] {taskinstance.py:2076} INFO - Dependencies all met for dep_context=non-requeueable deps ti=<TaskInstance: sales_pipeline.database_preparation manual__2024-05-28T22:15:19.089785+00:00 [queued]>
[2024-05-28T22:16:01.866+0000] {taskinstance.py:2076} INFO - Dependencies all met for dep_context=requeueable deps ti=<TaskInstance: sales_pipeline.database_preparation manual__2024-05-28T22:15:19.089785+00:00 [queued]>
[2024-05-28T22:16:01.867+0000] {taskinstance.py:2306} INFO - Starting attempt 2 of 2
[2024-05-28T22:16:01.880+0000] {taskinstance.py:2330} INFO - Executing <Task(PythonOperator): database_preparation> on 2024-05-28 22:15:19.089785+00:00
[2024-05-28T22:16:01.889+0000] {warnings.py:110} WARNING - /home/***/.local/lib/python3.12/site-packages/***/task/task_runner/standard_task_runner.py:61: DeprecationWarning: This process (pid=282) is multi-threaded, use of fork() may lead to deadlocks in the child.
  pid = os.fork()

[2024-05-28T22:16:01.890+0000] {standard_task_runner.py:63} INFO - Started process 284 to run task
[2024-05-28T22:16:01.890+0000] {standard_task_runner.py:90} INFO - Running: ['***', 'tasks', 'run', 'sales_pipeline', 'database_preparation', 'manual__2024-05-28T22:15:19.089785+00:00', '--job-id', '79', '--raw', '--subdir', 'DAGS_FOLDER/sales_data_pipeline.py', '--cfg-path', '/tmp/tmpdv0bj8nr']
[2024-05-28T22:16:01.892+0000] {standard_task_runner.py:91} INFO - Job 79: Subtask database_preparation
[2024-05-28T22:16:01.903+0000] {warnings.py:110} WARNING - /home/***/.local/lib/python3.12/site-packages/***/settings.py:195: DeprecationWarning: The sql_alchemy_conn option in [core] has been moved to the sql_alchemy_conn option in [database] - the old setting has been used, but please update your config.
  SQL_ALCHEMY_CONN = conf.get("database", "SQL_ALCHEMY_CONN")

[2024-05-28T22:16:01.931+0000] {task_command.py:426} INFO - Running <TaskInstance: sales_pipeline.database_preparation manual__2024-05-28T22:15:19.089785+00:00 [running]> on host 90e12a9d37bb
[2024-05-28T22:16:02.011+0000] {taskinstance.py:2648} INFO - Exporting env vars: AIRFLOW_CTX_DAG_OWNER='Mahmoud Mamdoh' AIRFLOW_CTX_DAG_ID='sales_pipeline' AIRFLOW_CTX_TASK_ID='database_preparation' AIRFLOW_CTX_EXECUTION_DATE='2024-05-28T22:15:19.089785+00:00' AIRFLOW_CTX_TRY_NUMBER='2' AIRFLOW_CTX_DAG_RUN_ID='manual__2024-05-28T22:15:19.089785+00:00'
[2024-05-28T22:16:02.012+0000] {taskinstance.py:430} INFO - ::endgroup::
[2024-05-28T22:16:02.031+0000] {sales_data_pipeline.py:46} ERROR - Error in database_preparation
Traceback (most recent call last):
  File "/opt/airflow/dags/sales_data_pipeline.py", line 40, in database_preparation
    db_credentials = load_credentials()
                     ^^^^^^^^^^^^^^^^^^
  File "/opt/airflow/dags/sales_data_pipeline.py", line 27, in load_credentials
    host = Variable.get("host")
           ^^^^^^^^^^^^^^^^^^^^
  File "/home/airflow/.local/lib/python3.12/site-packages/airflow/models/variable.py", line 143, in get
    raise KeyError(f"Variable {key} does not exist")
KeyError: 'Variable host does not exist'
[2024-05-28T22:16:02.033+0000] {python.py:237} INFO - Done. Returned value was: None
[2024-05-28T22:16:02.033+0000] {taskinstance.py:441} INFO - ::group::Post task execution logs
[2024-05-28T22:16:02.043+0000] {taskinstance.py:1206} INFO - Marking task as SUCCESS. dag_id=sales_pipeline, task_id=database_preparation, run_id=manual__2024-05-28T22:15:19.089785+00:00, execution_date=20240528T221519, start_date=20240528T221601, end_date=20240528T221602
[2024-05-28T22:16:02.063+0000] {local_task_job_runner.py:240} INFO - Task exited with return code 0
[2024-05-28T22:16:02.085+0000] {taskinstance.py:3498} INFO - 1 downstream tasks scheduled from follow-on schedule check
[2024-05-28T22:16:02.087+0000] {local_task_job_runner.py:222} INFO - ::endgroup::
