[2024-05-28T20:15:07.970+0000] {local_task_job_runner.py:120} INFO - ::group::Pre task execution logs
[2024-05-28T20:15:07.992+0000] {taskinstance.py:2076} INFO - Dependencies all met for dep_context=non-requeueable deps ti=<TaskInstance: sales_pipeline.data_delivery manual__2024-05-28T20:14:51.546418+00:00 [queued]>
[2024-05-28T20:15:07.998+0000] {taskinstance.py:2076} INFO - Dependencies all met for dep_context=requeueable deps ti=<TaskInstance: sales_pipeline.data_delivery manual__2024-05-28T20:14:51.546418+00:00 [queued]>
[2024-05-28T20:15:07.999+0000] {taskinstance.py:2306} INFO - Starting attempt 1 of 1
[2024-05-28T20:15:08.010+0000] {taskinstance.py:2330} INFO - Executing <Task(PythonOperator): data_delivery> on 2024-05-28 20:14:51.546418+00:00
[2024-05-28T20:15:08.019+0000] {warnings.py:110} WARNING - /home/***/.local/lib/python3.12/site-packages/***/task/task_runner/standard_task_runner.py:61: DeprecationWarning: This process (pid=129) is multi-threaded, use of fork() may lead to deadlocks in the child.
  pid = os.fork()

[2024-05-28T20:15:08.020+0000] {standard_task_runner.py:63} INFO - Started process 131 to run task
[2024-05-28T20:15:08.020+0000] {standard_task_runner.py:90} INFO - Running: ['***', 'tasks', 'run', 'sales_pipeline', 'data_delivery', 'manual__2024-05-28T20:14:51.546418+00:00', '--job-id', '28', '--raw', '--subdir', 'DAGS_FOLDER/sales_data_pipeline.py', '--cfg-path', '/tmp/tmpegd1tj3j']
[2024-05-28T20:15:08.022+0000] {standard_task_runner.py:91} INFO - Job 28: Subtask data_delivery
[2024-05-28T20:15:08.033+0000] {warnings.py:110} WARNING - /home/***/.local/lib/python3.12/site-packages/***/settings.py:195: DeprecationWarning: The sql_alchemy_conn option in [core] has been moved to the sql_alchemy_conn option in [database] - the old setting has been used, but please update your config.
  SQL_ALCHEMY_CONN = conf.get("database", "SQL_ALCHEMY_CONN")

[2024-05-28T20:15:08.060+0000] {task_command.py:426} INFO - Running <TaskInstance: sales_pipeline.data_delivery manual__2024-05-28T20:14:51.546418+00:00 [running]> on host 90e12a9d37bb
[2024-05-28T20:15:08.144+0000] {taskinstance.py:2648} INFO - Exporting env vars: AIRFLOW_CTX_DAG_OWNER='Mahmoud Mamdoh' AIRFLOW_CTX_DAG_ID='sales_pipeline' AIRFLOW_CTX_TASK_ID='data_delivery' AIRFLOW_CTX_EXECUTION_DATE='2024-05-28T20:14:51.546418+00:00' AIRFLOW_CTX_TRY_NUMBER='1' AIRFLOW_CTX_DAG_RUN_ID='manual__2024-05-28T20:14:51.546418+00:00'
[2024-05-28T20:15:08.145+0000] {taskinstance.py:430} INFO - ::endgroup::
[2024-05-28T20:15:08.157+0000] {sales_data_pipeline.py:54} INFO - data_delivery started
[2024-05-28T20:15:08.157+0000] {Load_data.py:10} INFO - Loading customer_df dimension...
[2024-05-28T20:15:08.186+0000] {tables_creation.py:47} INFO - Loading data into table DIM_CUSTOMERS...
[2024-05-28T20:15:08.189+0000] {db_utils.py:30} INFO - Connected to PostgreSQL database successfully
[2024-05-28T20:15:08.190+0000] {Load_data.py:19} ERROR - Error loading users dimension: cannot truncate a table referenced in a foreign key constraint
DETAIL:  Table "fact_sales" references "dim_customers".
HINT:  Truncate table "fact_sales" at the same time, or use TRUNCATE ... CASCADE.

[2024-05-28T20:15:08.191+0000] {Load_data.py:23} INFO - Loading customer dimension...
[2024-05-28T20:15:08.215+0000] {tables_creation.py:47} INFO - Loading data into table DIM_STORE...
[2024-05-28T20:15:08.218+0000] {db_utils.py:30} INFO - Connected to PostgreSQL database successfully
[2024-05-28T20:15:08.219+0000] {Load_data.py:29} ERROR - Error loading users dimension: cannot truncate a table referenced in a foreign key constraint
DETAIL:  Table "fact_sales" references "dim_store".
HINT:  Truncate table "fact_sales" at the same time, or use TRUNCATE ... CASCADE.

[2024-05-28T20:15:08.220+0000] {Load_data.py:33} INFO - Loading customer dimension...
[2024-05-28T20:15:08.265+0000] {tables_creation.py:47} INFO - Loading data into table DIM_PRODUCT...
[2024-05-28T20:15:08.269+0000] {db_utils.py:30} INFO - Connected to PostgreSQL database successfully
[2024-05-28T20:15:08.270+0000] {Load_data.py:42} ERROR - Error loading users dimension: cannot truncate a table referenced in a foreign key constraint
DETAIL:  Table "fact_sales" references "dim_product".
HINT:  Truncate table "fact_sales" at the same time, or use TRUNCATE ... CASCADE.

[2024-05-28T20:15:08.271+0000] {Load_data.py:46} INFO - Loading fact sales ...
[2024-05-28T20:15:08.360+0000] {tables_creation.py:47} INFO - Loading data into table FACT_SALES...
[2024-05-28T20:15:08.363+0000] {db_utils.py:30} INFO - Connected to PostgreSQL database successfully
[2024-05-28T20:15:08.384+0000] {Load_data.py:52} ERROR - Error loading sales fact: column "order_detail" of relation "fact_sales" does not exist
LINE 1: INSERT INTO FACT_SALES (order_id, order_detail, customer_id,...
                                          ^

[2024-05-28T20:15:08.392+0000] {sales_data_pipeline.py:59} INFO - data_delivery done
[2024-05-28T20:15:08.392+0000] {python.py:237} INFO - Done. Returned value was: None
[2024-05-28T20:15:08.393+0000] {taskinstance.py:441} INFO - ::group::Post task execution logs
[2024-05-28T20:15:08.402+0000] {taskinstance.py:1206} INFO - Marking task as SUCCESS. dag_id=sales_pipeline, task_id=data_delivery, run_id=manual__2024-05-28T20:14:51.546418+00:00, execution_date=20240528T201451, start_date=20240528T201507, end_date=20240528T201508
[2024-05-28T20:15:08.433+0000] {local_task_job_runner.py:240} INFO - Task exited with return code 0
[2024-05-28T20:15:08.448+0000] {taskinstance.py:3498} INFO - 0 downstream tasks scheduled from follow-on schedule check
[2024-05-28T20:15:08.449+0000] {local_task_job_runner.py:222} INFO - ::endgroup::
