[2024-05-28T11:09:29.972+0000] {local_task_job_runner.py:120} INFO - ::group::Pre task execution logs
[2024-05-28T11:09:30.148+0000] {taskinstance.py:2076} INFO - Dependencies all met for dep_context=non-requeueable deps ti=<TaskInstance: sales_pipeline.database_preparation manual__2024-05-28T11:09:28.428422+00:00 [queued]>
[2024-05-28T11:09:30.155+0000] {taskinstance.py:2076} INFO - Dependencies all met for dep_context=requeueable deps ti=<TaskInstance: sales_pipeline.database_preparation manual__2024-05-28T11:09:28.428422+00:00 [queued]>
[2024-05-28T11:09:30.155+0000] {taskinstance.py:2306} INFO - Starting attempt 1 of 1
[2024-05-28T11:09:30.169+0000] {taskinstance.py:2330} INFO - Executing <Task(PythonOperator): database_preparation> on 2024-05-28 11:09:28.428422+00:00
[2024-05-28T11:09:30.177+0000] {warnings.py:110} WARNING - /home/***/.local/lib/python3.12/site-packages/***/task/task_runner/standard_task_runner.py:61: DeprecationWarning: This process (pid=1380) is multi-threaded, use of fork() may lead to deadlocks in the child.
  pid = os.fork()

[2024-05-28T11:09:30.178+0000] {standard_task_runner.py:63} INFO - Started process 1382 to run task
[2024-05-28T11:09:30.178+0000] {standard_task_runner.py:90} INFO - Running: ['***', 'tasks', 'run', 'sales_pipeline', 'database_preparation', 'manual__2024-05-28T11:09:28.428422+00:00', '--job-id', '33', '--raw', '--subdir', 'DAGS_FOLDER/sales_data_pipeline.py', '--cfg-path', '/tmp/tmp9ak25gdo']
[2024-05-28T11:09:30.180+0000] {standard_task_runner.py:91} INFO - Job 33: Subtask database_preparation
[2024-05-28T11:09:30.218+0000] {task_command.py:426} INFO - Running <TaskInstance: sales_pipeline.database_preparation manual__2024-05-28T11:09:28.428422+00:00 [running]> on host 78f59380d06f
[2024-05-28T11:09:30.313+0000] {taskinstance.py:2648} INFO - Exporting env vars: AIRFLOW_CTX_DAG_OWNER='Mahmoud Mamdoh' AIRFLOW_CTX_DAG_ID='sales_pipeline' AIRFLOW_CTX_TASK_ID='database_preparation' AIRFLOW_CTX_EXECUTION_DATE='2024-05-28T11:09:28.428422+00:00' AIRFLOW_CTX_TRY_NUMBER='1' AIRFLOW_CTX_DAG_RUN_ID='manual__2024-05-28T11:09:28.428422+00:00'
[2024-05-28T11:09:30.314+0000] {taskinstance.py:430} INFO - ::endgroup::
[2024-05-28T11:09:30.330+0000] {sales_data_pipeline.py:36} INFO - database_preparation started
[2024-05-28T11:09:30.330+0000] {sales_data_pipeline.py:41} ERROR - Error in database_preparation
Traceback (most recent call last):
  File "/opt/airflow/dags/sales_data_pipeline.py", line 37, in database_preparation
    drop_tables(**db_credentials)
TypeError: drop_tables() got an unexpected keyword argument 'host'
[2024-05-28T11:09:30.331+0000] {python.py:237} INFO - Done. Returned value was: None
[2024-05-28T11:09:30.332+0000] {taskinstance.py:441} INFO - ::group::Post task execution logs
[2024-05-28T11:09:30.342+0000] {taskinstance.py:1206} INFO - Marking task as SUCCESS. dag_id=sales_pipeline, task_id=database_preparation, run_id=manual__2024-05-28T11:09:28.428422+00:00, execution_date=20240528T110928, start_date=20240528T110930, end_date=20240528T110930
[2024-05-28T11:09:30.391+0000] {local_task_job_runner.py:240} INFO - Task exited with return code 0
[2024-05-28T11:09:30.417+0000] {taskinstance.py:3498} INFO - 1 downstream tasks scheduled from follow-on schedule check
[2024-05-28T11:09:30.418+0000] {local_task_job_runner.py:222} INFO - ::endgroup::
