[2024-05-28T17:30:57.352+0000] {local_task_job_runner.py:120} INFO - ::group::Pre task execution logs
[2024-05-28T17:30:57.376+0000] {taskinstance.py:2076} INFO - Dependencies all met for dep_context=non-requeueable deps ti=<TaskInstance: sales_pipeline.database_preparation manual__2024-05-28T17:28:12.172790+00:00 [queued]>
[2024-05-28T17:30:57.384+0000] {taskinstance.py:2076} INFO - Dependencies all met for dep_context=requeueable deps ti=<TaskInstance: sales_pipeline.database_preparation manual__2024-05-28T17:28:12.172790+00:00 [queued]>
[2024-05-28T17:30:57.384+0000] {taskinstance.py:2306} INFO - Starting attempt 3 of 3
[2024-05-28T17:30:57.396+0000] {taskinstance.py:2330} INFO - Executing <Task(PythonOperator): database_preparation> on 2024-05-28 17:28:12.172790+00:00
[2024-05-28T17:30:57.404+0000] {warnings.py:110} WARNING - /home/***/.local/lib/python3.12/site-packages/***/task/task_runner/standard_task_runner.py:61: DeprecationWarning: This process (pid=93) is multi-threaded, use of fork() may lead to deadlocks in the child.
  pid = os.fork()

[2024-05-28T17:30:57.405+0000] {standard_task_runner.py:63} INFO - Started process 95 to run task
[2024-05-28T17:30:57.405+0000] {standard_task_runner.py:90} INFO - Running: ['***', 'tasks', 'run', 'sales_pipeline', 'database_preparation', 'manual__2024-05-28T17:28:12.172790+00:00', '--job-id', '20', '--raw', '--subdir', 'DAGS_FOLDER/sales_data_pipeline.py', '--cfg-path', '/tmp/tmpzrtc5d2i']
[2024-05-28T17:30:57.407+0000] {standard_task_runner.py:91} INFO - Job 20: Subtask database_preparation
[2024-05-28T17:30:57.418+0000] {warnings.py:110} WARNING - /home/***/.local/lib/python3.12/site-packages/***/settings.py:195: DeprecationWarning: The sql_alchemy_conn option in [core] has been moved to the sql_alchemy_conn option in [database] - the old setting has been used, but please update your config.
  SQL_ALCHEMY_CONN = conf.get("database", "SQL_ALCHEMY_CONN")

[2024-05-28T17:30:57.445+0000] {task_command.py:426} INFO - Running <TaskInstance: sales_pipeline.database_preparation manual__2024-05-28T17:28:12.172790+00:00 [running]> on host 03b4db1c7961
[2024-05-28T17:30:57.524+0000] {taskinstance.py:2648} INFO - Exporting env vars: AIRFLOW_CTX_DAG_OWNER='Mahmoud Mamdoh' AIRFLOW_CTX_DAG_ID='sales_pipeline' AIRFLOW_CTX_TASK_ID='database_preparation' AIRFLOW_CTX_EXECUTION_DATE='2024-05-28T17:28:12.172790+00:00' AIRFLOW_CTX_TRY_NUMBER='3' AIRFLOW_CTX_DAG_RUN_ID='manual__2024-05-28T17:28:12.172790+00:00'
[2024-05-28T17:30:57.525+0000] {taskinstance.py:430} INFO - ::endgroup::
[2024-05-28T17:30:57.537+0000] {sales_data_pipeline.py:36} INFO - database_preparation started
[2024-05-28T17:30:57.537+0000] {sales_data_pipeline.py:41} ERROR - Error in database_preparation
Traceback (most recent call last):
  File "/opt/airflow/dags/sales_data_pipeline.py", line 37, in database_preparation
    drop_tables(**db_credentials)
TypeError: drop_tables() got an unexpected keyword argument 'host'
[2024-05-28T17:30:57.538+0000] {python.py:237} INFO - Done. Returned value was: None
[2024-05-28T17:30:57.538+0000] {taskinstance.py:441} INFO - ::group::Post task execution logs
[2024-05-28T17:30:57.546+0000] {taskinstance.py:1206} INFO - Marking task as SUCCESS. dag_id=sales_pipeline, task_id=database_preparation, run_id=manual__2024-05-28T17:28:12.172790+00:00, execution_date=20240528T172812, start_date=20240528T173057, end_date=20240528T173057
[2024-05-28T17:30:57.578+0000] {local_task_job_runner.py:240} INFO - Task exited with return code 0
[2024-05-28T17:30:57.602+0000] {taskinstance.py:3498} INFO - 1 downstream tasks scheduled from follow-on schedule check
[2024-05-28T17:30:57.604+0000] {local_task_job_runner.py:222} INFO - ::endgroup::
