[2024-05-28T20:25:17.066+0000] {local_task_job_runner.py:120} INFO - ::group::Pre task execution logs
[2024-05-28T20:25:17.089+0000] {taskinstance.py:2076} INFO - Dependencies all met for dep_context=non-requeueable deps ti=<TaskInstance: sales_pipeline.data_delivery manual__2024-05-28T20:25:00.375788+00:00 [queued]>
[2024-05-28T20:25:17.096+0000] {taskinstance.py:2076} INFO - Dependencies all met for dep_context=requeueable deps ti=<TaskInstance: sales_pipeline.data_delivery manual__2024-05-28T20:25:00.375788+00:00 [queued]>
[2024-05-28T20:25:17.096+0000] {taskinstance.py:2306} INFO - Starting attempt 1 of 1
[2024-05-28T20:25:17.107+0000] {taskinstance.py:2330} INFO - Executing <Task(PythonOperator): data_delivery> on 2024-05-28 20:25:00.375788+00:00
[2024-05-28T20:25:17.116+0000] {warnings.py:110} WARNING - /home/***/.local/lib/python3.12/site-packages/***/task/task_runner/standard_task_runner.py:61: DeprecationWarning: This process (pid=165) is multi-threaded, use of fork() may lead to deadlocks in the child.
  pid = os.fork()

[2024-05-28T20:25:17.117+0000] {standard_task_runner.py:63} INFO - Started process 167 to run task
[2024-05-28T20:25:17.118+0000] {standard_task_runner.py:90} INFO - Running: ['***', 'tasks', 'run', 'sales_pipeline', 'data_delivery', 'manual__2024-05-28T20:25:00.375788+00:00', '--job-id', '40', '--raw', '--subdir', 'DAGS_FOLDER/sales_data_pipeline.py', '--cfg-path', '/tmp/tmp6m3j12z7']
[2024-05-28T20:25:17.120+0000] {standard_task_runner.py:91} INFO - Job 40: Subtask data_delivery
[2024-05-28T20:25:17.130+0000] {warnings.py:110} WARNING - /home/***/.local/lib/python3.12/site-packages/***/settings.py:195: DeprecationWarning: The sql_alchemy_conn option in [core] has been moved to the sql_alchemy_conn option in [database] - the old setting has been used, but please update your config.
  SQL_ALCHEMY_CONN = conf.get("database", "SQL_ALCHEMY_CONN")

[2024-05-28T20:25:17.158+0000] {task_command.py:426} INFO - Running <TaskInstance: sales_pipeline.data_delivery manual__2024-05-28T20:25:00.375788+00:00 [running]> on host 90e12a9d37bb
[2024-05-28T20:25:17.239+0000] {taskinstance.py:2648} INFO - Exporting env vars: AIRFLOW_CTX_DAG_OWNER='Mahmoud Mamdoh' AIRFLOW_CTX_DAG_ID='sales_pipeline' AIRFLOW_CTX_TASK_ID='data_delivery' AIRFLOW_CTX_EXECUTION_DATE='2024-05-28T20:25:00.375788+00:00' AIRFLOW_CTX_TRY_NUMBER='1' AIRFLOW_CTX_DAG_RUN_ID='manual__2024-05-28T20:25:00.375788+00:00'
[2024-05-28T20:25:17.240+0000] {taskinstance.py:430} INFO - ::endgroup::
[2024-05-28T20:25:17.252+0000] {sales_data_pipeline.py:54} INFO - data_delivery started
[2024-05-28T20:25:17.252+0000] {Load_data.py:10} INFO - Loading customer_df dimension...
[2024-05-28T20:25:17.260+0000] {tables_creation.py:47} INFO - Loading data into table DIM_CUSTOMERS...
[2024-05-28T20:25:17.263+0000] {db_utils.py:30} INFO - Connected to PostgreSQL database successfully
[2024-05-28T20:25:17.269+0000] {Load_data.py:19} ERROR - Error loading users dimension: column "customer_name" of relation "dim_customers" does not exist
LINE 1: INSERT INTO DIM_CUSTOMERS (customer_id, customer_name, segme...
                                                ^

[2024-05-28T20:25:17.269+0000] {Load_data.py:23} INFO - Loading customer dimension...
[2024-05-28T20:25:17.276+0000] {tables_creation.py:47} INFO - Loading data into table DIM_STORE...
[2024-05-28T20:25:17.278+0000] {db_utils.py:30} INFO - Connected to PostgreSQL database successfully
[2024-05-28T20:25:18.092+0000] {tables_creation.py:59} INFO - Data loaded successfully into table DIM_STORE
[2024-05-28T20:25:18.093+0000] {db_utils.py:39} INFO - PostgreSQL connection is closed
[2024-05-28T20:25:18.093+0000] {Load_data.py:29} INFO - store_df dimension loaded successfully
[2024-05-28T20:25:18.111+0000] {Load_data.py:36} INFO - Loading customer dimension...
[2024-05-28T20:25:18.127+0000] {tables_creation.py:47} INFO - Loading data into table DIM_PRODUCT...
[2024-05-28T20:25:18.130+0000] {db_utils.py:30} INFO - Connected to PostgreSQL database successfully
[2024-05-28T20:25:18.139+0000] {Load_data.py:45} ERROR - Error loading users dimension: column "product_name" of relation "dim_product" does not exist
LINE 1: INSERT INTO DIM_PRODUCT (product_id, product_name, subcatego...
                                             ^

[2024-05-28T20:25:18.141+0000] {Load_data.py:49} INFO - Loading fact sales ...
[2024-05-28T20:25:18.237+0000] {tables_creation.py:47} INFO - Loading data into table FACT_SALES...
[2024-05-28T20:25:18.241+0000] {db_utils.py:30} INFO - Connected to PostgreSQL database successfully
[2024-05-28T20:25:30.491+0000] {tables_creation.py:59} INFO - Data loaded successfully into table FACT_SALES
[2024-05-28T20:25:30.492+0000] {db_utils.py:39} INFO - PostgreSQL connection is closed
[2024-05-28T20:25:30.815+0000] {Load_data.py:53} INFO - Sales fact loaded successfully
[2024-05-28T20:25:30.818+0000] {sales_data_pipeline.py:59} INFO - data_delivery done
[2024-05-28T20:25:30.818+0000] {python.py:237} INFO - Done. Returned value was: None
[2024-05-28T20:25:30.819+0000] {taskinstance.py:441} INFO - ::group::Post task execution logs
[2024-05-28T20:25:30.827+0000] {taskinstance.py:1206} INFO - Marking task as SUCCESS. dag_id=sales_pipeline, task_id=data_delivery, run_id=manual__2024-05-28T20:25:00.375788+00:00, execution_date=20240528T202500, start_date=20240528T202517, end_date=20240528T202530
[2024-05-28T20:25:30.863+0000] {local_task_job_runner.py:240} INFO - Task exited with return code 0
[2024-05-28T20:25:30.877+0000] {taskinstance.py:3498} INFO - 0 downstream tasks scheduled from follow-on schedule check
[2024-05-28T20:25:30.879+0000] {local_task_job_runner.py:222} INFO - ::endgroup::
