[2024-05-28T18:18:15.926+0000] {local_task_job_runner.py:120} INFO - ::group::Pre task execution logs
[2024-05-28T18:18:15.950+0000] {taskinstance.py:2076} INFO - Dependencies all met for dep_context=non-requeueable deps ti=<TaskInstance: sales_pipeline.data_delivery manual__2024-05-28T18:17:59.574633+00:00 [queued]>
[2024-05-28T18:18:15.957+0000] {taskinstance.py:2076} INFO - Dependencies all met for dep_context=requeueable deps ti=<TaskInstance: sales_pipeline.data_delivery manual__2024-05-28T18:17:59.574633+00:00 [queued]>
[2024-05-28T18:18:15.957+0000] {taskinstance.py:2306} INFO - Starting attempt 1 of 1
[2024-05-28T18:18:15.971+0000] {taskinstance.py:2330} INFO - Executing <Task(PythonOperator): data_delivery> on 2024-05-28 18:17:59.574633+00:00
[2024-05-28T18:18:15.979+0000] {warnings.py:110} WARNING - /home/***/.local/lib/python3.12/site-packages/***/task/task_runner/standard_task_runner.py:61: DeprecationWarning: This process (pid=66) is multi-threaded, use of fork() may lead to deadlocks in the child.
  pid = os.fork()

[2024-05-28T18:18:15.980+0000] {standard_task_runner.py:63} INFO - Started process 68 to run task
[2024-05-28T18:18:15.981+0000] {standard_task_runner.py:90} INFO - Running: ['***', 'tasks', 'run', 'sales_pipeline', 'data_delivery', 'manual__2024-05-28T18:17:59.574633+00:00', '--job-id', '51', '--raw', '--subdir', 'DAGS_FOLDER/sales_data_pipeline.py', '--cfg-path', '/tmp/tmpocssyodm']
[2024-05-28T18:18:15.982+0000] {standard_task_runner.py:91} INFO - Job 51: Subtask data_delivery
[2024-05-28T18:18:15.992+0000] {warnings.py:110} WARNING - /home/***/.local/lib/python3.12/site-packages/***/settings.py:195: DeprecationWarning: The sql_alchemy_conn option in [core] has been moved to the sql_alchemy_conn option in [database] - the old setting has been used, but please update your config.
  SQL_ALCHEMY_CONN = conf.get("database", "SQL_ALCHEMY_CONN")

[2024-05-28T18:18:16.021+0000] {task_command.py:426} INFO - Running <TaskInstance: sales_pipeline.data_delivery manual__2024-05-28T18:17:59.574633+00:00 [running]> on host 21654332652c
[2024-05-28T18:18:16.101+0000] {taskinstance.py:2648} INFO - Exporting env vars: AIRFLOW_CTX_DAG_OWNER='Mahmoud Mamdoh' AIRFLOW_CTX_DAG_ID='sales_pipeline' AIRFLOW_CTX_TASK_ID='data_delivery' AIRFLOW_CTX_EXECUTION_DATE='2024-05-28T18:17:59.574633+00:00' AIRFLOW_CTX_TRY_NUMBER='1' AIRFLOW_CTX_DAG_RUN_ID='manual__2024-05-28T18:17:59.574633+00:00'
[2024-05-28T18:18:16.102+0000] {taskinstance.py:430} INFO - ::endgroup::
[2024-05-28T18:18:16.116+0000] {sales_data_pipeline.py:54} INFO - data_delivery started
[2024-05-28T18:18:16.116+0000] {sales_data_pipeline.py:61} ERROR - Error in data_delivery
Traceback (most recent call last):
  File "/opt/airflow/dags/sales_data_pipeline.py", line 55, in data_delivery
    load_customer_dim(**db_credentials)
TypeError: load_customer_dim() got an unexpected keyword argument 'host'
[2024-05-28T18:18:16.117+0000] {python.py:237} INFO - Done. Returned value was: None
[2024-05-28T18:18:16.117+0000] {taskinstance.py:441} INFO - ::group::Post task execution logs
[2024-05-28T18:18:16.125+0000] {taskinstance.py:1206} INFO - Marking task as SUCCESS. dag_id=sales_pipeline, task_id=data_delivery, run_id=manual__2024-05-28T18:17:59.574633+00:00, execution_date=20240528T181759, start_date=20240528T181815, end_date=20240528T181816
[2024-05-28T18:18:16.153+0000] {local_task_job_runner.py:240} INFO - Task exited with return code 0
[2024-05-28T18:18:16.171+0000] {taskinstance.py:3498} INFO - 0 downstream tasks scheduled from follow-on schedule check
[2024-05-28T18:18:16.172+0000] {local_task_job_runner.py:222} INFO - ::endgroup::
