[2024-05-28T20:16:37.652+0000] {local_task_job_runner.py:120} INFO - ::group::Pre task execution logs
[2024-05-28T20:16:37.673+0000] {taskinstance.py:2076} INFO - Dependencies all met for dep_context=non-requeueable deps ti=<TaskInstance: sales_pipeline.data_delivery manual__2024-05-28T20:16:22.024404+00:00 [queued]>
[2024-05-28T20:16:37.681+0000] {taskinstance.py:2076} INFO - Dependencies all met for dep_context=requeueable deps ti=<TaskInstance: sales_pipeline.data_delivery manual__2024-05-28T20:16:22.024404+00:00 [queued]>
[2024-05-28T20:16:37.682+0000] {taskinstance.py:2306} INFO - Starting attempt 1 of 1
[2024-05-28T20:16:37.692+0000] {taskinstance.py:2330} INFO - Executing <Task(PythonOperator): data_delivery> on 2024-05-28 20:16:22.024404+00:00
[2024-05-28T20:16:37.701+0000] {warnings.py:110} WARNING - /home/***/.local/lib/python3.12/site-packages/***/task/task_runner/standard_task_runner.py:61: DeprecationWarning: This process (pid=138) is multi-threaded, use of fork() may lead to deadlocks in the child.
  pid = os.fork()

[2024-05-28T20:16:37.702+0000] {standard_task_runner.py:63} INFO - Started process 140 to run task
[2024-05-28T20:16:37.702+0000] {standard_task_runner.py:90} INFO - Running: ['***', 'tasks', 'run', 'sales_pipeline', 'data_delivery', 'manual__2024-05-28T20:16:22.024404+00:00', '--job-id', '31', '--raw', '--subdir', 'DAGS_FOLDER/sales_data_pipeline.py', '--cfg-path', '/tmp/tmpk9e5a7v3']
[2024-05-28T20:16:37.704+0000] {standard_task_runner.py:91} INFO - Job 31: Subtask data_delivery
[2024-05-28T20:16:37.714+0000] {warnings.py:110} WARNING - /home/***/.local/lib/python3.12/site-packages/***/settings.py:195: DeprecationWarning: The sql_alchemy_conn option in [core] has been moved to the sql_alchemy_conn option in [database] - the old setting has been used, but please update your config.
  SQL_ALCHEMY_CONN = conf.get("database", "SQL_ALCHEMY_CONN")

[2024-05-28T20:16:37.741+0000] {task_command.py:426} INFO - Running <TaskInstance: sales_pipeline.data_delivery manual__2024-05-28T20:16:22.024404+00:00 [running]> on host 90e12a9d37bb
[2024-05-28T20:16:37.821+0000] {taskinstance.py:2648} INFO - Exporting env vars: AIRFLOW_CTX_DAG_OWNER='Mahmoud Mamdoh' AIRFLOW_CTX_DAG_ID='sales_pipeline' AIRFLOW_CTX_TASK_ID='data_delivery' AIRFLOW_CTX_EXECUTION_DATE='2024-05-28T20:16:22.024404+00:00' AIRFLOW_CTX_TRY_NUMBER='1' AIRFLOW_CTX_DAG_RUN_ID='manual__2024-05-28T20:16:22.024404+00:00'
[2024-05-28T20:16:37.822+0000] {taskinstance.py:430} INFO - ::endgroup::
[2024-05-28T20:16:37.836+0000] {sales_data_pipeline.py:54} INFO - data_delivery started
[2024-05-28T20:16:37.836+0000] {Load_data.py:10} INFO - Loading customer_df dimension...
[2024-05-28T20:16:37.863+0000] {tables_creation.py:47} INFO - Loading data into table DIM_CUSTOMERS...
[2024-05-28T20:16:37.866+0000] {db_utils.py:30} INFO - Connected to PostgreSQL database successfully
[2024-05-28T20:16:37.890+0000] {Load_data.py:19} ERROR - Error loading users dimension: duplicate key value violates unique constraint "dim_customers_pkey"
DETAIL:  Key (customer_id)=(PB-19210) already exists.

[2024-05-28T20:16:37.892+0000] {Load_data.py:23} INFO - Loading customer dimension...
[2024-05-28T20:16:37.916+0000] {tables_creation.py:47} INFO - Loading data into table DIM_STORE...
[2024-05-28T20:16:37.919+0000] {db_utils.py:30} INFO - Connected to PostgreSQL database successfully
[2024-05-28T20:16:37.929+0000] {Load_data.py:29} ERROR - Error loading users dimension: duplicate key value violates unique constraint "dim_store_pkey"
DETAIL:  Key (store_id)=(LOC2293) already exists.

[2024-05-28T20:16:37.930+0000] {Load_data.py:33} INFO - Loading customer dimension...
[2024-05-28T20:16:37.980+0000] {tables_creation.py:47} INFO - Loading data into table DIM_PRODUCT...
[2024-05-28T20:16:37.983+0000] {db_utils.py:30} INFO - Connected to PostgreSQL database successfully
[2024-05-28T20:16:38.005+0000] {Load_data.py:42} ERROR - Error loading users dimension: duplicate key value violates unique constraint "dim_product_pkey"
DETAIL:  Key (product_id)=(OFF-AP-10004512) already exists.

[2024-05-28T20:16:38.008+0000] {Load_data.py:46} INFO - Loading fact sales ...
[2024-05-28T20:16:38.114+0000] {tables_creation.py:47} INFO - Loading data into table FACT_SALES...
[2024-05-28T20:16:38.118+0000] {db_utils.py:30} INFO - Connected to PostgreSQL database successfully
[2024-05-28T20:16:50.262+0000] {tables_creation.py:59} INFO - Data loaded successfully into table FACT_SALES
[2024-05-28T20:16:50.262+0000] {db_utils.py:39} INFO - PostgreSQL connection is closed
[2024-05-28T20:16:50.595+0000] {Load_data.py:50} INFO - Sales fact loaded successfully
[2024-05-28T20:16:50.597+0000] {sales_data_pipeline.py:59} INFO - data_delivery done
[2024-05-28T20:16:50.598+0000] {python.py:237} INFO - Done. Returned value was: None
[2024-05-28T20:16:50.598+0000] {taskinstance.py:441} INFO - ::group::Post task execution logs
[2024-05-28T20:16:50.607+0000] {taskinstance.py:1206} INFO - Marking task as SUCCESS. dag_id=sales_pipeline, task_id=data_delivery, run_id=manual__2024-05-28T20:16:22.024404+00:00, execution_date=20240528T201622, start_date=20240528T201637, end_date=20240528T201650
[2024-05-28T20:16:50.646+0000] {local_task_job_runner.py:240} INFO - Task exited with return code 0
[2024-05-28T20:16:50.659+0000] {taskinstance.py:3498} INFO - 0 downstream tasks scheduled from follow-on schedule check
[2024-05-28T20:16:50.661+0000] {local_task_job_runner.py:222} INFO - ::endgroup::
