[2024-05-28T20:45:39.811+0000] {local_task_job_runner.py:120} INFO - ::group::Pre task execution logs
[2024-05-28T20:45:39.835+0000] {taskinstance.py:2076} INFO - Dependencies all met for dep_context=non-requeueable deps ti=<TaskInstance: sales_pipeline.data_delivery manual__2024-05-28T20:42:14.909820+00:00 [queued]>
[2024-05-28T20:45:39.843+0000] {taskinstance.py:2076} INFO - Dependencies all met for dep_context=requeueable deps ti=<TaskInstance: sales_pipeline.data_delivery manual__2024-05-28T20:42:14.909820+00:00 [queued]>
[2024-05-28T20:45:39.843+0000] {taskinstance.py:2306} INFO - Starting attempt 2 of 2
[2024-05-28T20:45:39.856+0000] {taskinstance.py:2330} INFO - Executing <Task(PythonOperator): data_delivery> on 2024-05-28 20:42:14.909820+00:00
[2024-05-28T20:45:39.866+0000] {warnings.py:110} WARNING - /home/***/.local/lib/python3.12/site-packages/***/task/task_runner/standard_task_runner.py:61: DeprecationWarning: This process (pid=213) is multi-threaded, use of fork() may lead to deadlocks in the child.
  pid = os.fork()

[2024-05-28T20:45:39.867+0000] {standard_task_runner.py:63} INFO - Started process 215 to run task
[2024-05-28T20:45:39.867+0000] {standard_task_runner.py:90} INFO - Running: ['***', 'tasks', 'run', 'sales_pipeline', 'data_delivery', 'manual__2024-05-28T20:42:14.909820+00:00', '--job-id', '56', '--raw', '--subdir', 'DAGS_FOLDER/sales_data_pipeline.py', '--cfg-path', '/tmp/tmpgqlqzem_']
[2024-05-28T20:45:39.870+0000] {standard_task_runner.py:91} INFO - Job 56: Subtask data_delivery
[2024-05-28T20:45:39.882+0000] {warnings.py:110} WARNING - /home/***/.local/lib/python3.12/site-packages/***/settings.py:195: DeprecationWarning: The sql_alchemy_conn option in [core] has been moved to the sql_alchemy_conn option in [database] - the old setting has been used, but please update your config.
  SQL_ALCHEMY_CONN = conf.get("database", "SQL_ALCHEMY_CONN")

[2024-05-28T20:45:39.914+0000] {task_command.py:426} INFO - Running <TaskInstance: sales_pipeline.data_delivery manual__2024-05-28T20:42:14.909820+00:00 [running]> on host 90e12a9d37bb
[2024-05-28T20:45:40.002+0000] {taskinstance.py:2648} INFO - Exporting env vars: AIRFLOW_CTX_DAG_OWNER='Mahmoud Mamdoh' AIRFLOW_CTX_DAG_ID='sales_pipeline' AIRFLOW_CTX_TASK_ID='data_delivery' AIRFLOW_CTX_EXECUTION_DATE='2024-05-28T20:42:14.909820+00:00' AIRFLOW_CTX_TRY_NUMBER='2' AIRFLOW_CTX_DAG_RUN_ID='manual__2024-05-28T20:42:14.909820+00:00'
[2024-05-28T20:45:40.003+0000] {taskinstance.py:430} INFO - ::endgroup::
[2024-05-28T20:45:40.016+0000] {sales_data_pipeline.py:54} INFO - data_delivery started
[2024-05-28T20:45:40.016+0000] {Load_data.py:10} INFO - Loading customer_df dimension...
[2024-05-28T20:45:40.025+0000] {tables_creation.py:47} INFO - Loading data into table DIM_CUSTOMERS...
[2024-05-28T20:45:40.030+0000] {db_utils.py:30} INFO - Connected to PostgreSQL database successfully
[2024-05-28T20:45:40.037+0000] {Load_data.py:19} ERROR - Error loading users dimension: column "customer_naem" of relation "dim_customers" does not exist
LINE 1: INSERT INTO DIM_CUSTOMERS (customer_id, customer_naem, segme...
                                                ^

[2024-05-28T20:45:40.038+0000] {Load_data.py:23} INFO - Loading customer dimension...
[2024-05-28T20:45:40.043+0000] {tables_creation.py:47} INFO - Loading data into table DIM_STORE...
[2024-05-28T20:45:40.047+0000] {db_utils.py:30} INFO - Connected to PostgreSQL database successfully
[2024-05-28T20:45:40.948+0000] {tables_creation.py:59} INFO - Data loaded successfully into table DIM_STORE
[2024-05-28T20:45:40.948+0000] {db_utils.py:39} INFO - PostgreSQL connection is closed
[2024-05-28T20:45:40.949+0000] {Load_data.py:29} INFO - store_df dimension loaded successfully
[2024-05-28T20:45:40.965+0000] {Load_data.py:36} INFO - Loading customer dimension...
[2024-05-28T20:45:40.980+0000] {tables_creation.py:47} INFO - Loading data into table DIM_PRODUCT...
[2024-05-28T20:45:40.983+0000] {db_utils.py:30} INFO - Connected to PostgreSQL database successfully
[2024-05-28T20:45:43.183+0000] {tables_creation.py:59} INFO - Data loaded successfully into table DIM_PRODUCT
[2024-05-28T20:45:43.184+0000] {db_utils.py:39} INFO - PostgreSQL connection is closed
[2024-05-28T20:45:43.184+0000] {Load_data.py:42} INFO - product_df dimension loaded successfully
[2024-05-28T20:45:43.234+0000] {Load_data.py:49} INFO - Loading fact sales ...
[2024-05-28T20:45:43.321+0000] {tables_creation.py:47} INFO - Loading data into table FACT_SALES...
[2024-05-28T20:45:43.324+0000] {db_utils.py:30} INFO - Connected to PostgreSQL database successfully
[2024-05-28T20:45:55.796+0000] {tables_creation.py:59} INFO - Data loaded successfully into table FACT_SALES
[2024-05-28T20:45:55.797+0000] {db_utils.py:39} INFO - PostgreSQL connection is closed
[2024-05-28T20:45:56.121+0000] {Load_data.py:53} INFO - Sales fact loaded successfully
[2024-05-28T20:45:56.124+0000] {sales_data_pipeline.py:59} INFO - data_delivery done
[2024-05-28T20:45:56.124+0000] {python.py:237} INFO - Done. Returned value was: None
[2024-05-28T20:45:56.125+0000] {taskinstance.py:441} INFO - ::group::Post task execution logs
[2024-05-28T20:45:56.133+0000] {taskinstance.py:1206} INFO - Marking task as SUCCESS. dag_id=sales_pipeline, task_id=data_delivery, run_id=manual__2024-05-28T20:42:14.909820+00:00, execution_date=20240528T204214, start_date=20240528T204539, end_date=20240528T204556
[2024-05-28T20:45:56.181+0000] {local_task_job_runner.py:240} INFO - Task exited with return code 0
[2024-05-28T20:45:56.195+0000] {taskinstance.py:3498} INFO - 0 downstream tasks scheduled from follow-on schedule check
[2024-05-28T20:45:56.196+0000] {local_task_job_runner.py:222} INFO - ::endgroup::
